2020-05-26 14:11:24,169 - __main__ - INFO - Initiated env_app.py
2020-05-26 14:11:28,137 - __main__ - INFO - env_app.py script complete.
2020-05-26 14:27:03,749 - __main__ - INFO - Initiated env_app.py
2020-05-26 14:27:23,208 - __main__ - INFO - env_app.py script complete.
2020-05-26 14:30:37,261 - __main__ - INFO - Initiated env_app.py
2020-05-26 14:30:40,227 - __main__ - INFO - env_app.py script complete.
2020-05-26 14:35:47,119 - __main__ - INFO - Initiated env_app.py
2020-05-26 14:35:49,834 - __main__ - INFO - env_app.py script complete.
2020-05-26 14:36:35,751 - __main__ - INFO - Initiated env_app.py
2020-05-26 14:36:38,456 - __main__ - INFO - env_app.py script complete.
2020-05-26 14:37:49,717 - __main__ - INFO - Initiated env_app.py
2020-05-26 14:37:52,412 - __main__ - INFO - env_app.py script complete.
2020-05-26 14:39:18,155 - __main__ - INFO - Initiated env_app.py
2020-05-26 14:39:20,864 - __main__ - INFO - env_app.py script complete.
2020-05-26 14:42:35,564 - module_1 - INFO - Message one logged successfully.
2020-05-26 14:42:35,564 - module_1 - INFO - Message two logged successfully.
2020-05-26 14:42:35,564 - module_1 - ERROR - name 'pd' is not defined
Traceback (most recent call last):
  File "C:\Users\CRTUCKER\Documents\Libraries-and-Resources\logging_app\bin\module_1.py", line 43, in log_error_message_one
    pd.read_csv('no_module_named_pd.csv')
NameError: name 'pd' is not defined
2020-05-26 14:42:35,565 - module_1 - INFO - Message three logged successfully.
